Workbook

Sheet Assumptions
B1: Alexandria Library, Inc — Financial Model
B2: Numbers.xlsx
B4: Pricing
B5: Sovereignty — with kin | C5: 5 | D5: $/month
B6: Sovereignty — without kin | C6: 10 | D6: $/month
B7: Examined Life — with kin | C7: 15 | D7: $/month
B8: Examined Life — without kin | C8: 20 | D8: $/month
B9: % of users with 3+ active kin | C9: 0.6 | D9: Assumption
B10: Blended Sovereignty ARPU | C10: =ROUND(C9*C5+(1-C9)*C6,0) | D10: $5×0.6 + $10×0.4 = $7, then 10% quarterly / 20% annual discounts
B11: Effective Sovereignty ARPU (after discounts) | C11: 6
B12: Blended Examined Life ARPU | C12: =ROUND(C9*C7+(1-C9)*C8,0)
B13: Effective Examined Life ARPU (after discounts) | C13: 15
B15: Payment Processing
B16: ACH rate (Sovereignty) | C16: 0.008 | D16: 0.8% flat, no per-txn fee
B17: Stripe rate (Examined Life) | C17: 0.029 | D17: 2.9% + $0.30/txn
B18: Stripe per-txn fee | C18: 0.3
B20: Growth
B21: Year 1 — Sovereignty users (EOY) | C21: 2000
B22: Sovereignty growth (YoY) | D22: Y2: 150%, Y3: 120%, Y4: 90%, Y5: 60%
B23: Year 2 growth | C23: 1.5
B24: Year 3 growth | C24: 1.2
B25: Year 4 growth | C25: 0.9
B26: Year 5 growth | C26: 0.6
B27: Year 1 — Sov → EL conversion | C27: 0.08
B28: Annual conversion improvement | C28: 0.02 | D28: +2pp/year
B29: EL organic growth (direct users) | C29: 0.3 | D29: 30% YoY
B30: Monthly churn — Sovereignty | C30: 0.04
B31: Monthly churn — Examined Life | C31: 0.02
B33: Company Opex (Monthly)
B34: Claude Max | C34: 100 | D34: anthropic.com
B35: Railway | C35: 1 | D35: railway.com
B36: Total monthly opex | C36: =C34+C35
B37: Annual opex | C37: =C36*12
B38: Free stack | D38: GitHub, Google Drive, Vercel, UptimeRobot, Google Cloud, Claude Code — all $0
B40: Legal & One-Time Costs
B41: Stripe Atlas (Delaware C-Corp) | C41: 500 | D41: Paid
B42: California foreign qualification | C42: 150
B43: Delaware franchise tax (annual) | C43: 400
B44: California franchise tax (annual) | C44: 800
B45: Registered agent (annual) | C45: 150
...

Sheet 5-Year Projections
B1: Alexandria Library, Inc — 5-Year Projections
B3: Users | C3: Year 1 | D3: Year 2 | E3: Year 3 | F3: Year 4 | G3: Year 5
B4: Sovereignty users (EOY) | C4: =Assumptions!C21 | D4: =ROUND(C4*(1+Assumptions!C23),0) | E4: =ROUND(D4*(1+Assumptions!C24),0) | F4: =ROUND(E4*(1+Assumptions!C25),0) | G4: =ROUND(F4*(1+Assumptions!C26),0)
B5: Sov → EL conversion | C5: =Assumptions!C27 | D5: =C5+Assumptions!C28 | E5: =D5+Assumptions!C28 | F5: =E5+Assumptions!C28 | G5: =F5+Assumptions!C28
B6: Converted to Examined Life | C6: =ROUND(C4*C5,0) | D6: =ROUND(D4*D5,0) | E6: =ROUND(E4*E5,0) | F6: =ROUND(F4*F5,0) | G6: =ROUND(G4*G5,0)
B7: Examined Life (direct, cumulative) | C7: 50 | D7: =ROUND(C7*(1+Assumptions!C29),0) | E7: =ROUND(D7*(1+Assumptions!C29),0) | F7: =ROUND(E7*(1+Assumptions!C29),0) | G7: =ROUND(F7*(1+Assumptions!C29),0)
B8: Total Examined Life users | C8: =C6+C7 | D8: =D6+D7 | E8: =E6+E7 | F8: =F6+F7 | G8: =G6+G7
B9: Total paying users | C9: =C4+C8 | D9: =D4+D8 | E9: =E4+E8 | F9: =F4+F8 | G9: =G4+G8
B11: Annual Revenue | C11: Year 1 | D11: Year 2 | E11: Year 3 | F11: Year 4 | G11: Year 5
B12: Sovereignty subscription revenue | C12: =C4*Assumptions!C11*12 | D12: =D4*Assumptions!C11*12 | E12: =E4*Assumptions!C11*12 | F12: =F4*Assumptions!C11*12 | G12: =G4*Assumptions!C11*12
B13: Examined Life subscription revenue | C13: =C8*Assumptions!C13*12 | D13: =D8*Assumptions!C13*12 | E13: =E8*Assumptions!C13*12 | F13: =F8*Assumptions!C13*12 | G13: =G8*Assumptions!C13*12
B14: Total subscription revenue | C14: =C12+C13 | D14: =D12+D13 | E14: =E12+E13 | F14: =F12+F13 | G14: =G12+G13
B15: % growth | D15: =(D14-C14)/C14 | E15: =(E14-D14)/D14 | F15: =(F14-E14)/E14 | G15: =(G14-F14)/F14
B17: Library for Labs (B2B) | C17: 0 | D17: 0 | E17: =Assumptions!C61*Assumptions!C60 | F17: =Assumptions!C62*Assumptions!C60 | G17: =Assumptions!C63*Assumptions!C60
B18: Library for People (rev-share) | C18: 0 | D18: 0 | E18: 0 | F18: =Assumptions!C64 | G18: =Assumptions!C64*2
B19: Total Library revenue | C19: =C17+C18 | D19: =D17+D18 | E19: =E17+E18 | F19: =F17+F18 | G19: =G17+G18
B21: TOTAL REVENUE | C21: =C14+C19 | D21: =D14+D19 | E21: =E14+E19 | F21: =F14+F19 | G21: =G14+G19
B23: Annual Costs | C23: Year 1 | D23: Year 2 | E23: Year 3 | F23: Year 4 | G23: Year 5
B24: Infrastructure | C24: =Assumptions!C37 | D24: =Assumptions!C37 | E24: =Assumptions!C37 | F24: =Assumptions!C37 | G24: =Assumptions!C37
B25: Payment processing | C25: =ROUND(C12*Assumptions!C16 + C13*Assumptions!C17 + C8*12*Assumptions!C18, 0) | D25: =ROUND(D12*Assumptions!C16 + D13*Assumptions!C17 + D8*12*Assumptions!C18, 0) | E25: =ROUND(E12*Assumptions!C16 + E13*Assumptions!C17 + E8*12*Assumptions!C18, 0) | F25: =ROUND(F12*Assumptions!C16 + F13*Assumptions!C17 + F8*12*Assumptions!C18, 0) | G25: =ROUND(G12*Assumptions!C16 + G13*Assumptions!C17 + G8*12*Assumptions!C18, 0)
B26: Taxes, permits, filings | C26: =Assumptions!C48+Assumptions!C49 | D26: =Assumptions!C49 | E26: =Assumptions!C49 | F26: =Assumptions!C49 | G26: =Assumptions!C49
B27: Ads / marketing | C27: =Assumptions!C56*12 | D27: =Assumptions!C57*12 | E27: =Assumptions!C57*12 | F27: =Assumptions!C57*12 | G27: =Assumptions!C57*12
B28: Founder living costs | C28: =Assumptions!C53 | D28: =Assumptions!C53 | E28: =Assumptions!C53 | F28: =Assumptions!C53 | G28: =Assumptions!C53
B29: Total costs | C29: =SUM(C24:C28) | D29: =SUM(D24:D28) | E29: =SUM(E24:E28) | F29: =SUM(F24:F28) | G29: =SUM(G24:G28)
B31: Profitability | C31: Year 1 | D31: Year 2 | E31: Year 3 | F31: Year 4 | G31: Year 5
B32: Net income | C32: =C21-C29 | D32: =D21-D29 | E32: =E21-E29 | F32: =F21-F29 | G32: =G21-G29
B33: % margin | C33: =C32/C21 | D33: =D32/D21 | E33: =E32/E21 | F33: =F32/F21 | G33: =G32/G21
B34: Cumulative net income | C34: =C32 | D34: =C34+D32 | E34: =D34+E32 | F34: =E34+F32 | G34: =F34+G32
B36: Valuation
B37: Year 5 ARR | G37: =G21
B38: Exit multiple | G38: =Assumptions!C69
B39: Implied valuation | G39: =G37*G38
B41: Months to breakeven (Year 1) | D41: =ROUND(C29/C21*12,1)
