Workbook

Sheet Assumptions
B1: Alexandria Library, Inc — Financial Model
B3: Pricing
B4: Sovereignty — with kin | C4: 5 | D4: $/month
B5: Sovereignty — without kin | C5: 10 | D5: $/month
B6: Examined Life — with kin | C6: 15 | D6: $/month
B7: Examined Life — without kin | C7: 20 | D7: $/month
B8: % of users with 3+ active kin | C8: 0.6
B9: Effective Sovereignty ARPU | C9: 6 | D9: Blended $7, after quarterly/annual discounts
B10: Effective Examined Life ARPU | C10: 15 | D10: Blended $17, after discounts
B12: Payment Processing
B13: ACH rate (Sovereignty) | C13: 0.008 | D13: 0.8% flat, no per-txn fee
B14: Stripe % rate (Examined Life) | C14: 0.029 | D14: 2.9%
B15: Stripe per-txn fee | C15: 0.3 | D15: $0.30/txn
B17: Growth
B18: Year 1 Sovereignty users (EOY) | C18: 2000
B19: Year 2 growth | C19: 1.5
B20: Year 3 growth | C20: 1.2
B21: Year 4 growth | C21: 0.9
B22: Year 5 growth | C22: 0.6
B23: Year 1 Sov → EL conversion | C23: 0.08
B24: Annual conversion improvement | C24: 0.02 | D24: +2pp/year
B25: EL direct users (Year 1 seed) | C25: 50
B26: EL organic growth | C26: 0.3 | D26: 30% YoY
B27: Monthly churn — Sovereignty | C27: 0.04
B28: Monthly churn — Examined Life | C28: 0.02
B30: Company Opex (Monthly)
B31: Claude Max | C31: 100 | D31: anthropic.com
B32: Fly.io | C32: 2 | D32: fly.io
B33: Total monthly opex | C33: =C31+C32
B34: Annual opex | C34: =C33*12
B35: Free stack | D35: GitHub, Google Drive, Vercel, UptimeRobot, Google Cloud, Claude Code — all $0
B37: Legal & Filing Costs
B38: Stripe Atlas (Delaware C-Corp) | C38: 500 | D38: Paid
B39: California foreign qualification | C39: 150
B40: Total one-time | C40: =C38+C39
B41: Delaware franchise tax (annual) | C41: 400
B42: California franchise tax (annual) | C42: 800
B43: Registered agent (annual) | C43: 150
B44: CPA — federal return | C44: 1500 | D44: Estimate
B45: CPA — state return(s) | C45: 500 | D45: Estimate
...

Sheet 5-Year Projections
B1: Alexandria Library, Inc — 5-Year Projections
D3: Year 1 | E3: Year 2 | F3: Year 3 | G3: Year 4 | H3: Year 5
B4: Users
B5: Sovereignty users (EOY) | D5: =Assumptions!C18 | E5: =ROUND(D5*(1+Assumptions!C19),0) | F5: =ROUND(E5*(1+Assumptions!C20),0) | G5: =ROUND(F5*(1+Assumptions!C21),0) | H5: =ROUND(G5*(1+Assumptions!C22),0)
C6: Sov → EL conversion | D6: =Assumptions!C23 | E6: =D6+Assumptions!C24 | F6: =E6+Assumptions!C24 | G6: =F6+Assumptions!C24 | H6: =G6+Assumptions!C24
B7: Converted to Examined Life | D7: =ROUND(D5*D6,0) | E7: =ROUND(E5*E6,0) | F7: =ROUND(F5*F6,0) | G7: =ROUND(G5*G6,0) | H7: =ROUND(H5*H6,0)
B8: Examined Life (direct) | D8: =Assumptions!C25 | E8: =ROUND(D8*(1+Assumptions!C26),0) | F8: =ROUND(E8*(1+Assumptions!C26),0) | G8: =ROUND(F8*(1+Assumptions!C26),0) | H8: =ROUND(G8*(1+Assumptions!C26),0)
B9: Total Examined Life users | D9: =D7+D8 | E9: =E7+E8 | F9: =F7+F8 | G9: =G7+G8 | H9: =H7+H8
B10: Total paying users | D10: =D5+D9 | E10: =E5+E9 | F10: =F5+F9 | G10: =G5+G9 | H10: =H5+H9
B12: Revenue
B13: Sovereignty subscriptions | D13: =D5*Assumptions!C9*12 | E13: =E5*Assumptions!C9*12 | F13: =F5*Assumptions!C9*12 | G13: =G5*Assumptions!C9*12 | H13: =H5*Assumptions!C9*12
C14: % growth | E14: =E13/D13-1 | F14: =F13/E13-1 | G14: =G13/F13-1 | H14: =H13/G13-1
B15: Examined Life subscriptions | D15: =D9*Assumptions!C10*12 | E15: =E9*Assumptions!C10*12 | F15: =F9*Assumptions!C10*12 | G15: =G9*Assumptions!C10*12 | H15: =H9*Assumptions!C10*12
B16: Total subscription revenue | D16: =D13+D15 | E16: =E13+E15 | F16: =F13+F15 | G16: =G13+G15 | H16: =H13+H15
B18: Library for Labs (B2B) | D18: 0 | E18: 0 | F18: =Assumptions!C58*Assumptions!C57 | G18: =Assumptions!C59*Assumptions!C57 | H18: =Assumptions!C60*Assumptions!C57
B19: Library for People | D19: 0 | E19: 0 | F19: 0 | G19: =Assumptions!C61 | H19: =Assumptions!C61*2
B20: Total Library revenue | D20: =D18+D19 | E20: =E18+E19 | F20: =F18+F19 | G20: =G18+G19 | H20: =H18+H19
B22: TOTAL REVENUE | D22: =D16+D20 | E22: =E16+E20 | F22: =F16+F20 | G22: =G16+G20 | H22: =H16+H20
C23: % growth | E23: =E22/D22-1 | F23: =F22/E22-1 | G23: =G22/F22-1 | H23: =H22/G22-1
B25: Costs
B26: Infrastructure | D26: =Assumptions!C34 | E26: =Assumptions!C34 | F26: =Assumptions!C34 | G26: =Assumptions!C34 | H26: =Assumptions!C34
B27: Payment processing | D27: =ROUND(D13*Assumptions!C13+D15*Assumptions!C14+D9*12*Assumptions!C15,0) | E27: =ROUND(E13*Assumptions!C13+E15*Assumptions!C14+E9*12*Assumptions!C15,0) | F27: =ROUND(F13*Assumptions!C13+F15*Assumptions!C14+F9*12*Assumptions!C15,0) | G27: =ROUND(G13*Assumptions!C13+G15*Assumptions!C14+G9*12*Assumptions!C15,0) | H27: =ROUND(H13*Assumptions!C13+H15*Assumptions!C14+H9*12*Assumptions!C15,0)
B28: Taxes, permits, filings | D28: =Assumptions!C40+Assumptions!C46 | E28: =Assumptions!C46 | F28: =Assumptions!C46 | G28: =Assumptions!C46 | H28: =Assumptions!C46
B29: Ads / marketing | D29: =Assumptions!C53*12 | E29: =Assumptions!C54*12 | F29: =Assumptions!C54*12 | G29: =Assumptions!C54*12 | H29: =Assumptions!C54*12
B30: Founder living costs | D30: =Assumptions!C50 | E30: =Assumptions!C50 | F30: =Assumptions!C50 | G30: =Assumptions!C50 | H30: =Assumptions!C50
B31: Total costs | D31: =SUM(D26:D30) | E31: =SUM(E26:E30) | F31: =SUM(F26:F30) | G31: =SUM(G26:G30) | H31: =SUM(H26:H30)
B33: Profitability
B34: Net income | D34: =D22-D31 | E34: =E22-E31 | F34: =F22-F31 | G34: =G22-G31 | H34: =H22-H31
C35: % margin | D35: =D34/D22 | E35: =E34/E22 | F35: =F34/F22 | G35: =G34/G22 | H35: =H34/H22
B36: Cumulative net income | D36: =D34 | E36: =D36+E34 | F36: =E36+F34 | G36: =F36+G34 | H36: =G36+H34
B38: Valuation
B39: Year 5 ARR | H39: =H22
B40: Exit multiple | H40: =Assumptions!C66
B41: Implied valuation | H41: =H39*H40
